Workbook

Sheet NAM HÀ
A1: THẺ QUY TẮC VIRAL · KÊNH HEALTH COACH NAM HÀ
A2: Rút từ 30 video Nam Hà nói trực tiếp (facebook.com/Healthcoachnamha, 1 triệu theo dõi), chọn từ 950 Reels gần nhất theo lượt xem; đã loại video chữ và video chữ gắn mặt. Đo ngày 08/10/2026. Số liệu từng video, dàn ý theo giây và bài học ở sheet "Số liệu Nam Hà".
A4: SỐ CHÍNH
A5: # | B5: Chỉ số | D5: Giá trị | E5: Ghi chú
A6: 1 | B6: Video đã phân tích | D6: 30 video | E6: Nam Hà nói trực tiếp, lấy theo lượt xem cao nhất. Gồm 6 danh sách ngắn, 8 bài tập làm mẫu, 7 mẹo/giảng 1–3 phút, 5 video có bán, 4 video dài.
A7: 2 | B7: Bối cảnh toàn kênh | D7: 8/100 | E7: Số video Nam Hà nói trong 100 video nhiều view nhất của kênh. 92 video còn lại là video chữ (cao nhất 9,2 triệu). Người nói là định dạng xây tin và bán hàng của kênh, không phải định dạng kéo view lớn nhất.
A8: 3 | B8: Trung vị lượt xem · 30 video | D8: =MEDIAN('Số liệu Nam Hà'!I5:I34) -> 390500 | E8: Video thấp nhất trong 30 video: 138K.
A9: 4 | B9: Video lớn nhất | D9: =MAX('Số liệu Nam Hà'!I5:I34) -> 2100000 | E9: Khắc tinh của bệnh tật · 0:25 · 03/10/2026 · 4,9K chia sẻ. Đạt 2,1 triệu chỉ sau 5 ngày.
A10: 5 | B10: Trung vị lượt xem theo dạng | D10: ="Bài tập "&ROUND(MEDIAN('Số liệu Nam Hà'!I11:I18)/1000,0)&"K · Danh sách ≤60 giây "&ROUND(MEDIAN('Số liệu Nam Hà'!I5:I10)/1000,0)&"K · Dài "&ROUND(MEDIAN('Số liệu Nam Hà'!I31:I34)/1000,0)&"K · Có bán "&ROUND(MEDIAN('Số liệu Nam Hà'!I26:I30)/1000,0)&"K · Mẹo/giảng 1–3 phút "&ROUND(MEDIAN('Số liệu Nam Hà'!I19:I25)/1000,0)&"K" -> Bài tập 617K · Danh sách ≤60 giây 592K · Dài 308K · Có bán 289K · Mẹo/giảng 1–3 phút 213K | E10: Hai dạng thắng: bài tập làm mẫu và danh sách nhanh dưới 1 phút. Mẹo/giảng 1–3 phút không có danh sách nhanh hay làm mẫu thì thấp nhất.
A11: 6 | B11: Chia sẻ / cảm xúc theo dạng | D11: ="Bài tập "&TEXT(MEDIAN('Số liệu Nam Hà'!O11:O18),"0%")&" · Danh sách ≤60 giây "&TEXT(MEDIAN('Số liệu Nam Hà'!O5:O10),"0%")&" · Có bán "&TEXT(MEDIAN('Số liệu Nam Hà'!O26:O30),"0%") -> Bài tập 22% · Danh sách ≤60 giây 15% · Có bán 7% | E11: Bài tập là thứ người xem lưu và gửi cho người nhà nhiều nhất. Video có bán gần như không được chia sẻ (video bán thuần: 18 chia sẻ).
A12: 7 | B12: Bình luận / 1.000 lượt xem cao nhất | D12: =MAX('Số liệu Nam Hà'!N5:N34) -> 5.4013158 | E12: "3 sai lầm khi ăn trái cây" 5,4 (luận điểm ngược đám đông) và "Ai vòng bụng trên 80cm" 4,6 (gọi đích danh bằng số đo).
A13: 8 | B13: Độ dài trung vị · 26 video ngắn | D13: =MEDIAN('Số liệu Nam Hà'!H5:H30) -> 0.001193287 | E13: Danh sách nhanh 25–60 giây; bài tập 1:14–2:37; 4 video dài 11–16 phút vẫn đạt 159K–376K.
A14: 9 | B14: Nhịp danh sách nhanh | D14: =ROUND('Số liệu Nam Hà'!Q5,1)&" giây/ý (2,1 triệu) · "&ROUND('Số liệu Nam Hà'!Q7,1)&" giây/ý (670K)" -> 2.3 giây/ý (2,1 triệu) · 4 giây/ý (670K) | E14: Mỗi ý chỉ một câu + một sticker; không giải thích.
A15: 10 | B15: Thân bài đánh số | D15: =COUNTIF('Số liệu Nam Hà'!P5:P34,">=2")&"/30" -> 22/30 | E15: "Thứ nhất / Động tác 1" hiện bằng chữ vàng.
A16: 11 | B16: Con số trong tiêu đề hoặc caption | D16: =COUNTIF('Số liệu Nam Hà'!R5:R34,"Có")&"/30" -> 21/30 | E16: Số ý, số phút, số đo, mốc tuổi.
A17: 12 | B17: Kết bằng câu chào chữ ký | D17: =COUNTIF('Số liệu Nam Hà'!U5:U34,"Có")&"/30" -> 12/30 | E17: "Biết ơn và sớm hẹn gặp lại, xin chào!" + vẫy tay: nhận diện bằng âm thanh.
A18: 13 | B18: Có nhắc sản phẩm | D18: =COUNTIF('Số liệu Nam Hà'!S5:S34,"Có")&"/30" -> 6/30 | E18: Sữa hạt ngũ cốc và dầu tràm, luôn đặt ở cuối video hoặc làm ý cuối của danh sách.
A19: 14 | B19: Cụm đau lưng – vai gáy | D19: =COUNTIF('Số liệu Nam Hà'!F5:F34,"Đau lưng – vai gáy")&" video · "&ROUND(SUMIF('Số liệu Nam Hà'!F5:F34,"Đau lưng – vai gáy",'Số liệu Nam Hà'!I5:I34)/1000000,1)&" triệu lượt xem" -> 7 video · 5.6 triệu lượt xem | E19: Cùng một khuôn quay, đổi động tác, áo, bối cảnh. Video thấp nhất cụm vẫn 265K.
A20: 15 | B20: Video mới | D20: =COUNTIF('Số liệu Nam Hà'!D5:D34,">="&DATE(2026,8,15))&"/30 đăng từ 15/08/2026" -> 8/30 đăng từ 15/08/2026 | E20: 4/5 video người nói lớn nhất nằm trong nhóm này: kênh đang ở giai đoạn đà lên của dạng bài tập.
A22: A. BỘ QUY TẮC VIRAL
A23: Mức độ: Bắt buộc = làm ở mọi video · Nên = làm khi phù hợp · Thử nghiệm = chạy thử nhỏ, đo rồi mới nhân rộng (DNA quyết định 129–130). Page nội dung được dùng hook mạnh, nhưng luôn giữ 5 lằn ranh sự thật ở sheet "Luật chung" của file phân vai 14 page.
A24: # | B24: Nhóm | C24: Quy tắc | D24: Làm thế nào | E24: Bằng chứng từ kênh Nam Hà | F24: Áp dụng cho Bác sĩ Hội | G24: Mức độ
A25: 1 | B25: Định dạng | C25: Người nói trực tiếp, nhìn thẳng máy, khung ngang ngực, tay diễn liên tục | D25: Mic cài áo, cười, tay đếm số theo ý và chỉ sang sticker. Mặt luôn nằm ở 1/3 giữa khung. | E25: 30/30 video. Lớn nhất 2,1 triệu; 8 video vượt 700K. | F25: Bác sĩ Hội nói trực tiếp, giọng 70% chuyên gia, 30% gần gũi (DNA ch.8). Dùng tay đếm "thứ nhất, thứ hai" để người xem bám nhịp. | G25: Bắt buộc
A26: 2 | B26: Chủ đề | C26: Vấn đề cơ thể ai cũng có + cách tự làm tại nhà | D26: Đau lưng, vai gáy, mệt mỏi, mất ngủ, vòng bụng, ăn gì – kiêng gì, uống nước, thói quen buổi sáng. Không nói về thuốc, xét nghiệm, ca hiếm. | E26: 30/30 video là vấn đề phổ thông kèm việc làm được ngay; không video nào nói về thuốc hay xét nghiệm. | F26: Chọn vấn đề tiêu hóa phổ thông: đầy hơi sau ăn (P3, P7), ợ chua đêm (P1), ăn tối muộn, bữa sáng (P8), ngồi lâu (P10), mất ngủ – stress (P12). | G26: Bắt buộc
A27: 3 | B27: Cụm chủ đề | C27: Khi một chủ đề nổ, làm cả cụm bằng cùng một khuôn | D27: Giữ khuôn quay và cấu trúc; đổi động tác, góc đau, áo, bối cảnh. Làm thêm một bản dài cho chủ đề đó. | E27: Cụm đau lưng – vai gáy 7 video, từ 265K đến 1,5 triệu. Tiền đình: bản 74 giây 201K + bản 11 phút 159K. | F27: Video vượt 2 lần trung vị page → làm cụm 5–8 video trong lãnh thổ page đó (Luật chung 6). Mỗi video quay mới (Luật chung 1–2). | G27: Bắt buộc
A28: 4 | B28: Cụm chủ đề | C28: Quay lại chủ đề đã thắng sau vài tháng bằng kịch bản mới | D28: Giữ dàn ý, viết lại câu, đổi số ý, quay mới. | E28: "5 việc sáng sớm" (4/2025, 289K) → "4 điều sáng sớm" (1/2026, 194K, 696 bình luận), dùng lại cả câu chữ đắt. | F28: Luật chung 2: không đăng lại file cũ; được làm lại ý tưởng với hook mới, ghi vào Sổ chủ đề. | G28: Nên
A29: 5 | B29: Tiêu đề | C29: Box tiêu đề chữ hoa 2–3 dòng ngay khung đầu, đồng thời là ảnh bìa | D29: Chữ trắng/vàng trên nền xanh, đặt ngang ngực, giữ 2–3 giây. Video dài: thanh tiêu đề cố định trên và dưới suốt video. | E29: 24/26 video ngắn mở bằng box; 2 video còn lại vào thẳng ý 1 bằng chữ vàng. 4/4 video dài dùng thanh tiêu đề cố định. | F29: Màu box theo nhận diện từng page (Luật chung 3). | G29: Bắt buộc
A30: 6 | B30: Tiêu đề | C30: Công thức: [vấn đề / đối tượng] + [kết quả có hình ảnh] + [dễ làm] | D30: Kết quả nhìn thấy được ("eo con kiến", "60 tuổi cũng chẳng già") + "đơn giản / tại nhà / nhà nào cũng cần / rẻ như cho". | E30: 709K lá ổi "eo con kiến"; 381K "60 tuổi cũng chẳng già"; 477K mẹo muỗi "nhà nào cũng cần". | F30: Kết quả phải là lợi ích có thật, không hứa khỏi (lằn ranh 3): "bụng nhẹ hẳn sau bữa tối", "ngủ một mạch tới sáng". Xem mục C. | G30: Bắt buộc
A31: 7 | B31: Tiêu đề | C31: Có con số trong tiêu đề hoặc caption | D31: Số ý (3 động tác, 4 việc), số phút (15 phút), số đo (80cm), mốc tuổi (60 tuổi), lượng nhỏ (2 miếng). | E31: 21/30 video. | F31: Công thức 34–39 DNA ch.14.11. Con số phải thật (lằn ranh 1). | G31: Nên
A32: 8 | B32: Hook lời | C32: Giây 0–3: nhắc lại tiêu đề hoặc nói ngay ý 1. Không chào, không giới thiệu | D32: Câu đầu tiên chính là tiêu đề, kèm chữ vàng và sticker bật ra. | E32: Video 2,1 triệu vào ý 1 ở giây 0,3. Không video ngắn nào mở bằng lời chào (theo phụ đề). | F32: Hook 3 tầng DNA 14.25 nén vào 3 giây: gọi đúng tình trạng → mâu thuẫn → lời hứa. | G32: Bắt buộc
A33: 9 | B33: Hook lời | C33: Mở bằng việc sai mà ai cũng đang làm, diễn lại trước máy | D33: Diễn lại động tác sai ("đừng có đấm như thế này nữa"), rồi một câu vì sao làm mãi không hết. | E33: 4 video bài tập lớn nhất đều mở kiểu này: 1,5 triệu · 1,2 triệu · 987K · 728K. | F33: "Đừng ngả lưng ra ghế ngay sau bữa tối nữa", "ợ chua mà cứ nằm xuống ngay" (P1, P3). Không trách người bệnh (DNA 14.34 mục 9). | G33: Bắt buộc
A34: 10 | B34: Hook lời | C34: Hạ rào cản ngay sau hook | D34: "Không cần tới phòng tập", "tập mọi lúc mọi nơi", "không cần khởi động", "vài nguyên liệu trong bếp", "rẻ như cho", "chưa đầy 2 phút". | E34: 13/30 video có câu hạ rào cản trong 20 giây đầu. | F34: "Không cần kiêng khổ sở", "làm ngay trong bếp nhà mình", "ngồi ở bàn làm việc cũng làm được" (P8, P10). | G34: Bắt buộc
A35: 11 | B35: Hook lời | C35: Gọi đích danh người xem bằng một con số họ tự đo được | D35: "Ai [số đo / số năm / giờ giấc] đừng bỏ lỡ video này". | E35: "Ai vòng bụng trên 80cm": 1,4K bình luận, 4,6 bình luận/1.000 lượt xem. | F35: "Ai uống thuốc dạ dày trên 3 tháng…" (P13), "Ai hay ăn tối sau 8 giờ…" (P1). Công thức DNA 14.19. | G35: Thử nghiệm
A36: 12 | B36: Hook lời | C36: Vay uy tín trong 10 giây đầu | D36: Tục ngữ, "theo Đông y", "khoa học đã ghi nhận", chuỗi số liệu giải phẫu. | E36: "Ngạn ngữ Trung Hoa có câu…" 539K; tục ngữ thắt lưng 305K; "bắp chân là trái tim thứ hai… 26 xương, 30 khớp". | F36: Bác sĩ Hội có uy tín thật: "Ở phòng khám tôi gặp rất nhiều…", "theo y học cổ truyền…" khi có cơ sở. Số liệu phải có nguồn (lằn ranh 1). | G36: Nên
... A51: 27 | B51: Tránh | C51: Những thứ kéo video xuống ở kênh này | D51: Video chỉ bán hàng; giảng 1–3 phút không có danh sách nhanh hay làm mẫu; lợi ích dồn quá nhiều làm mất tin. | E51: Video bán thuần 149K, 18 chia sẻ. Nhóm mẹo/giảng 1–3 phút: trung vị 213K, thấp nhất 5 dạng. | F51: Soát bằng mục D trước khi đăng. | G51: Nên
A53: B1. KHUNG DANH SÁCH NHANH 25–40 GIÂY (8–11 ý, 2–4 giây mỗi ý)
A54: Theo video 2,1 triệu và 670K. Mẫu: "Khắc tinh của dạ dày yếu" (P8). Bác sĩ duyệt từng cặp trước khi quay.
A55: # | B55: Giây | C55: Phần | D55: Việc phải làm | E55: Cách kênh Nam Hà làm | F55: Mẫu cho Bác sĩ Hội | G55: Độ dài lời
A56: 1 | B56: 0–2 giây | C56: Box tiêu đề + ý 1 | D56: Không chào. Ảnh bìa là box tiêu đề. Nói ngay ý 1, sticker bật ra. | E56: Giây 0,3 đã là ý 1 "Mắt mờ: sợ nhất cà rốt". | F56: Box: "KHẮC TINH CỦA DẠ DÀY YẾU – ÍT AI ĐỂ Ý". Lời: "Đầy hơi: sợ nhất đi bộ chậm 10 phút sau ăn." | G56: 8–12 tiếng
A57: 2 | B57: 2–28 giây | C57: Ý 2 → ý 9 | D57: Mỗi ý một câu cùng khuôn, sticker bên trái, tay chỉ sang. | E57: 11 ý, khoảng 2,3 giây/ý, mỗi ý một sticker. | F57: "Ợ chua đêm: sợ nhất ăn tối trước 7 giờ. Táo bón: sợ nhất rau xanh và đủ nước…" | G57: 8–12 tiếng/ý
...

Sheet Số liệu Nam Hà
A1: Số liệu 30 video · Health coach Nam Hà
A2: Kênh facebook.com/Healthcoachnamha · 1 triệu người theo dõi · đo ngày 08/10/2026. Đã quét 950 Reels gần nhất; chọn 30 video Nam Hà nói trực tiếp có lượt xem cao nhất (hạng 17–222 trên toàn kênh), loại video chữ và video chữ gắn mặt. Xếp theo 5 dạng; trong mỗi dạng xếp theo lượt xem.
A4: Dạng | B4: # trên lưới (hạng lượt xem) | C4: Link Reel | D4: Ngày đăng | E4: Tiêu đề trên màn hình | F4: Cụm chủ đề | G4: Kiểu mở đầu (0–10 giây) | H4: Thời lượng | I4: Lượt xem | J4: Cảm xúc | K4: Bình luận | L4: Chia sẻ | M4: Cảm xúc / lượt xem | N4: Bình luận / 1.000 lượt xem | O4: Chia sẻ / cảm xúc | P4: Số ý đánh số | Q4: Giây / ý | R4: Con số trong tiêu đề hoặc caption | S4: Nhắc sản phẩm | T4: Lời mời cuối video | U4: Câu chào chữ ký | V4: Dàn ý theo giây (đọc từ phụ đề in trên video) | W4: Vì sao chạy / bài học
A5: Danh sách / mẹo ≤ 60 giây | B5: 17 | C5: https://www.facebook.com/reel/2114972765771948 | D5: 46298 | E5: Khắc tinh của bệnh tật không phải ai cũng biết | F5: Ăn uống – thực phẩm | G5: Không chào, không dẫn: giây 0,3 đã vào ý 1 bằng chữ vàng + sticker | H5: 0.00029513889 | I5: 2100000 | J5: 28000 | K5: 520 | L5: 4900 | M5: =J5/I5 -> 0.013333333 | N5: =K5/I5*1000 -> 0.24761905 | O5: =L5/J5 -> 0.175 | P5: 11 | Q5: =IF(P5>0,H5*86400/P5,"") -> 2.3181818 | R5: Không | S5: Không | T5: Không (kết ở ý cuối) | U5: Không thấy | V5: 0,3s ý 1 'Mắt mờ: sợ nhất cà rốt' (sticker con mắt) → mỗi ~2,3 giây một cặp 'bệnh: sợ nhất thực phẩm' (cảm lạnh – tía tô, mất ngủ – hạt sen, viêm dạ dày – nghệ, táo bón – khoai lang, thiếu kẽm – hạt bí, thiếu canxi – mè đen, tiểu buốt – râu ngô, mất nước – nước dừa, nhiệt miệng – diếp cá) → hết ở giây 25, không lời mời. | W5: Danh sách cặp siêu nhanh: xem một lần không nhớ hết nên xem lại và lưu. 4,9K chia sẻ (17,5% số cảm xúc); đạt 2,1 triệu sau 5 ngày.
A6: Danh sách / mẹo ≤ 60 giây | B6: 80 | C6: https://www.facebook.com/reel/1073139771715391 | D6: 46234 | E6: Lá ổi nấu thế này ngũ tạng sạch mỡ, eo con kiến | F6: Ăn uống – thực phẩm | G6: Box tiêu đề → nhắc lại bằng lời + sticker lá ổi, bác sĩ cầm dấu '?' | H6: 0.00061689815 | I6: 709000 | J6: 13900 | K6: 755 | L6: 2100 | M6: =J6/I6 -> 0.019605078 | N6: =K6/I6*1000 -> 1.0648801 | O6: =L6/J6 -> 0.15107914 | P6: 3 | Q6: =IF(P6>0,H6*86400/P6,"") -> 17.766667 | R6: Có | S6: Không | T6: Lưu + lan tỏa | U6: Không thấy | V6: 0s box → 2,6s nhắc lại tiêu đề bằng lời → (1) lá ổi + gừng: ấm người, giảm tích mỡ sau ăn, bớt đầy hơi (ảnh AI ly trà, mâm cỗ) → (2) lá ổi + chanh: chuyển hóa mỡ sau bữa nhiều đạm → (3) lá ổi + mật ong: dễ uống, bớt nặng bụng → 43s 'nhớ lưu về áp dụng' → 46s 'đừng quên lan tỏa'. | W6: Nguyên liệu rẻ, quen + kết quả bằng hình ảnh cơ thể ('eo con kiến'). 13,9K cảm xúc, cao thứ 3 trong 30 video.
A7: Danh sách / mẹo ≤ 60 giây | B7: 82 | C7: https://www.facebook.com/reel/844976855308507 | D7: 46284 | E7: Muốn bớt ốm đau thì hạn chế ăn các thực phẩm sau | F7: Ăn uống – thực phẩm | G7: Box → 'cả đời nhớ hạn chế…' + sticker STOP | H7: 0.00032523148 | I7: 670000 | J7: 8800 | K7: 531 | L7: 1300 | M7: =J7/I7 -> 0.013134328 | N7: =K7/I7*1000 -> 0.79253731 | O7: =L7/J7 -> 0.14772727 | P7: 7 | Q7: =IF(P7>0,H7*86400/P7,"") -> 4.0142857 | R7: Không | S7: Không | T7: Lưu + lan tỏa | U7: Có | V7: 0s box → 2,7s 'cả đời nhớ hạn chế' (sticker STOP) → 7 món, ~2,5 giây/món, sticker món ăn bật cạnh mặt: mì tôm, xúc xích, đồ ăn nhanh, đồ hộp, trà sữa – nước ngọt, khoai tây chiên, đồ ăn vặt → 22,8s 'cả nhà nhớ lưu lại' → 'lan tỏa' → 27,9s vẫy tay chào chữ ký. | W7: Danh sách 'đừng ăn' toàn món ai cũng ăn: người xem tự soi và gửi cho người nhà.
A8: Danh sách / mẹo ≤ 60 giây | B8: 103 | C8: https://www.facebook.com/reel/4842899612609127 | D8: 46166 | E8: 15 phút gác chân lên tường | F8: Thói quen hằng ngày – sống thọ | G8: Chữ vàng con số + lợi ích ngay giây 0, rồi hạ rào cản 'không cần khởi động' | H8: 0.00069444444 | I8: 514000 | J8: 6200 | K8: 335 | L8: 423 | M8: =J8/I8 -> 0.012062257 | N8: =K8/I8*1000 -> 0.65175097 | O8: =L8/J8 -> 0.068225806 | P8: 9 | Q8: =IF(P8>0,H8*86400/P8,"") -> 6.6666667 | R8: Có | S8: Không | T8: Không thấy | U8: Có | V8: 0s '15 phút gác chân lên tường' → 'hiệu quả bất ngờ' → 'đơn giản mà lợi cho sức khỏe và sắc đẹp' → 'không cần khởi động, không chuẩn bị gì' → b-roll người làm mẫu → 24,6s 9 lợi ích ~2,7 giây/ý, sticker nội tạng → 59,7s chào chữ ký. | W8: Một hành động nhỏ có số phút + 9 lợi ích dồn dập. Phần 'lợi ích' nhiều chỗ quá mức (thải độc gan thận, trẻ hóa nội tạng).
A9: Danh sách / mẹo ≤ 60 giây | B9: 120 | C9: https://www.facebook.com/reel/2132121324080456 | D9: 46283 | E9: Mệt mỏi là cơ thể đang bị thiếu hụt các chất cần thiết | F9: Ăn uống – thực phẩm | G9: Box → từ giây 2 vào ngay nhịp 'triệu chứng ↔ chất thiếu' | H9: 0.0005162037 | I9: 433000 | J9: 8500 | K9: 413 | L9: 1300 | M9: =J9/I9 -> 0.019630485 | N9: =K9/I9*1000 -> 0.95381062 | O9: =L9/J9 -> 0.15294118 | P9: 16 | Q9: =IF(P9>0,H9*86400/P9,"") -> 2.7875 | R9: Không | S9: Không | T9: Lưu + lan tỏa | U9: Không thấy | V9: Mỗi ~2 giây một nhịp: sticker triệu chứng bên trái ↔ sticker chất bên phải, tay chỉ qua lại (chuột rút – Mg, đau xương – vitamin D, hụt hơi – đạm, mắt – vitamin A, tóc bạc sớm, móng giòn – kẽm…) → 38,5s 'xem xong nhớ lưu lại' → 'đừng quên lan tỏa'. | W9: Biến cảm giác mơ hồ (mệt) thành bảng tự soi; nhịp tay trái – phải giữ mắt.
A10: Danh sách / mẹo ≤ 60 giây | B10: 133 | C10: https://www.facebook.com/reel/1150584123950233 | D10: 46008 | E10: Mắt thâm tan biến đơn giản tại nhà | F10: Mẹo nhà – làm đẹp | G10: Box → nỗi lo ngoại hình: hốc hác, già hơn tuổi (b-roll) | H10: 0.00065972222 | I10: 368000 | J10: 4700 | K10: 265 | L10: 629 | M10: =J10/I10 -> 0.012771739 | N10: =K10/I10*1000 -> 0.7201087 | O10: =L10/J10 -> 0.13382979 | P10: 1 | Q10: =IF(P10>0,H10*86400/P10,"") -> 57 | R10: Không | S10: Không | T10: Lan tỏa + follow | U10: Không thấy | V10: 0s box → 2,8s 'chỉ với cách làm đơn giản tại nhà' → b-roll cô gái quầng thâm, 'trông hốc hác, già hơn tuổi' → nguyên nhân (thiếu ngủ, rượu, thuốc lá) → 23s 'trí tuệ cổ xưa… nhớ lưu về' → cà chua + nước cốt chanh + nghệ, thoa 15 phút → 49s lan tỏa → 54s 'nhớ follow để nhận thêm giá trị' (icon nút FOLLOW). | W10: Đánh vào ngoại hình + công thức 3 nguyên liệu trong bếp.
A11: Bài tập làm mẫu | B11: 37 | C11: https://www.facebook.com/reel/1111510108494817 | D11: 46288 | E11: Đau mỏi vai cổ gáy lâu năm thì nhớ tập ngay | F11: Đau lưng – vai gáy | G11: Tay xoa cổ + box → 'có đấm có lắc tới mùa quýt năm sau' | H11: 0.0018148148 | I11: 1500000 | J11: 18600 | K11: 2300 | L11: 3500 | M11: =J11/I11 -> 0.0124 | N11: =K11/I11*1000 -> 1.5333333 | O11: =L11/J11 -> 0.18817204 | P11: 5 | Q11: =IF(P11>0,H11*86400/P11,"") -> 31.36 | R11: Không | S11: Không | T11: Không thấy | U11: Không thấy | V11: 0s xoa cổ + box → 7s xoa bóp mãi không khỏi → 14s gốc là nhóm cơ vai gáy (b-roll) → 21s áp lực lên 7 đốt sống cổ (3D) → 28s 'Nam Hà bật mí 5 động tác vung tay' → động tác 1–5, mỗi động tác 50–100 cái + lợi ích → 'chia 2–3 set mỗi ngày'. | W11: Thói quen sai ai cũng làm + giải pháp làm ngay không dụng cụ. 3,5K chia sẻ, 2,3K bình luận.
A12: Bài tập làm mẫu | B12: 51 | C12: https://www.facebook.com/reel/1063029479678493 | D12: 46281 | E12: Đau lưng, đau dây thần kinh tọa Nam Hà chỉ cách | F12: Đau lưng – vai gáy | G12: Tay ôm lưng + box → 'đừng có đấm như thế này nữa' | H12: 0.0011296296 | I12: 1200000 | J12: 9500 | K12: 457 | L12: 2200 | M12: =J12/I12 -> 0.0079166667 | N12: =K12/I12*1000 -> 0.38083333 | O12: =L12/J12 -> 0.23157895 | P12: 4 | Q12: =IF(P12>0,H12*86400/P12,"") -> 24.4 | R12: Có | S12: Không | T12: Không thấy | U12: Không thấy | V12: 0s ôm lưng + box → 4,6s 'đừng có đấm như thế này nữa' → 9s 'không bao giờ hết đau lưng' (3D cột sống) → 13s '4 động tác' → 18s 'kiên trì 7–10 ngày cải thiện 50–80%' → 26–85s nằm thảm làm mẫu, 20–30 lần, giữ thở 1 phút → 88s ngồi lại chốt. | W12: Mở bằng động tác sai đang làm + mốc thời gian. Con số 50–80% không có nguồn.
A13: Bài tập làm mẫu | B13: 59 | C13: https://www.facebook.com/reel/1084624890576136 | D13: 46255 | E13: 5 động tác thần kỳ chữa lành mọi tổn thương vai cổ gáy | F13: Đau lưng – vai gáy | G13: Tay ôm cổ + box → 'có lắc tới 2030' → 'phải nói tới bao giờ mới chịu hiểu' | H13: 0.0013900463 | I13: 987000 | J13: 6600 | K13: 352 | L13: 2400 | M13: =J13/I13 -> 0.0066869301 | N13: =K13/I13*1000 -> 0.35663627 | O13: =L13/J13 -> 0.36363636 | P13: 5 | Q13: =IF(P13>0,H13*86400/P13,"") -> 24.02 | R13: Có | S13: Không | T13: Không thấy | U13: Không thấy | V13: 0s ôm cổ + box → 5,6s 'có lắc tới 2030' → 11s 'Nam Hà phải nói tới bao giờ…' → 16s cơ xương khớp lệch (3D) → 22s 'hiệu quả cực kỳ tuyệt vời' → 5 động tác, 50–100 lần, b-roll người đau chen giữa, ví 'như cánh chim' → 109s 'chỉ cần 7 ngày' → '50–80% tùy sự cam kết'. | W13: Giọng anh cả trách yêu tạo gần gũi. Chia sẻ/cảm xúc 36%, cao nhất 30 video.
A14: Bài tập làm mẫu | B14: 78 | C14: https://www.facebook.com/reel/28118810981090789 | D14: 46258 | E14: Đau lưng, đau dây thần kinh tọa tập ngay bài này | F14: Đau lưng – vai gáy | G14: Tay ôm lưng + box → 'đừng đấm nữa, đấm tới 2030 cũng không hết' | H14: 0.0013993056 | I14: 728000 | J14: 5800 | K14: 352 | L14: 1400 | M14: =J14/I14 -> 0.007967033 | N14: =K14/I14*1000 -> 0.48351648 | O14: =L14/J14 -> 0.24137931 | P14: 3 | Q14: =IF(P14>0,H14*86400/P14,"") -> 40.3 | R14: Có | S14: Có | T14: Giới thiệu dầu tràm | U14: Không thấy | V14: 0s box → 5,7s 'đừng có đấm như thế này nữa' → 11s đấm mãi không hết (b-roll) → 16,6s '3 động tác, không cần tập nhiều' → động tác 1–3, 50–100 lần, hỏi 'mỗi ngày 50–100 cái được không ạ' → 55s 'khắc tinh của đau chân' → 99s cầm chai dầu tràm: lưu thông khí huyết, cảm cúm, đau nhức. | W14: Bài tập giá trị trước, sản phẩm liên quan (xoa bóp) ở 20 giây cuối.
A15: Bài tập làm mẫu | B15: 107 | C15: https://www.facebook.com/reel/1596096095385583 | D15: 46266 | E15: Tan biến đau lưng, thần kinh tọa, đau chân, khỏe mạnh khớp gối | F15: Đau lưng – vai gáy | G15: Box + giơ 1 ngón tay → 'không cần tới phòng tập' | H15: 0.0015740741 | I15: 505000 | J15: 6400 | K15: 492 | L15: 1800 | M15: =J15/I15 -> 0.012673267 | N15: =K15/I15*1000 -> 0.97425743 | O15: =L15/J15 -> 0.28125 | P15: 3 | Q15: =IF(P15>0,H15*86400/P15,"") -> 45.333333 | R15: Có | S15: Không | T15: Không thấy | U15: Không thấy | V15: 0s box → 6,4s chữ vàng nhắc lại + sticker → 12,5s 'không cần tới phòng tập' → 18,7s 'hiệu quả không thể nghĩ bàn' → 3 động tác ngồi, 20–30 và 30–50 lần, 3D xương chậu chen giữa → 'làm càng nhiều hông càng linh hoạt'. | W15: Cùng khuôn cụm đau lưng; tiêu đề gom nhiều vùng đau để chạm nhiều người.
A16: Bài tập làm mẫu | B16: 123 | C16: https://www.facebook.com/reel/1022943776797706 | D16: 46196 | E16: 3 động tác cực tốt cho ai đau lưng, thần kinh tọa | F16: Đau lưng – vai gáy | G16: Box + vẫy tay → 'tập mọi lúc mọi nơi' | H16: 0.0015069444 | I16: 410000 | J16: 5300 | K16: 332 | L16: 1000 | M16: =J16/I16 -> 0.012926829 | N16: =K16/I16*1000 -> 0.8097561 | O16: =L16/J16 -> 0.18867925 | P16: 3 | Q16: =IF(P16>0,H16*86400/P16,"") -> 43.4 | R16: Có | S16: Không | T16: Không thấy | U16: Không thấy | V16: 0s box → 6s 'cực kỳ hiệu quả, tập mọi lúc mọi nơi' (3D hông) → động tác 1–3, 30–50 lần, giữ thở 2 phút, 3D dây thần kinh tọa → kết 'hiệu quả rất là cao'. | W16: Khuôn bài tập lặp lại vẫn 410K: người xem đã quen định dạng.
... A34: Video dài 11–16 phút | B34: 211 | C34: https://www.facebook.com/reel/1898701794354353 | D34: 46006 | E34: 5 cách đưa máu lên não ào ào · Ngủ ngon hơn mỗi ngày | F34: Giấc ngủ – tuần hoàn não | G34: Thanh tiêu đề: '5 cách đưa máu lên não ào ào' | H34: 0.0077465278 | I34: 159000 | J34: 2400 | K34: 202 | L34: 139 | M34: =J34/I34 -> 0.01509434 | N34: =K34/I34*1000 -> 1.2704403 | O34: =L34/J34 -> 0.057916667 | P34: 5 | Q34: =IF(P34>0,H34*86400/P34,"") -> 133.86 | R34: Có | S34: Không rõ | T34: Không xem hết (video dài) | U34: Không thấy | V34: 11 phút. Thanh trên '5 CÁCH ĐƯA MÁU LÊN NÃO ÀO ÀO', dưới 'NGỦ NGON HƠN MỖI NGÀY'. Giảng ở vườn, b-roll người mất ngủ. | W34: Bản dài của chủ đề tiền đình (bản 74 giây: 201K).
A36: Tổng hợp theo dạng (công thức)
A37: Dạng | B37: Số video | E37: Chỉ số | H37: Thời lượng | I37: Lượt xem | J37: Cảm xúc | K37: Bình luận | L37: Chia sẻ | M37: Cảm xúc / lượt xem | N37: Bình luận / 1.000 | O37: Chia sẻ / cảm xúc | P37: Số ý | Q37: Giây / ý | R37: Có con số | S37: Có sản phẩm | U37: Chào chữ ký
A38: Danh sách / mẹo ≤ 60 giây | B38: =COUNTA(I5:I10) -> 6 | E38: Trung vị (đếm 'Có' ở 3 cột cuối) | H38: =MEDIAN(H5:H10) -> 0.00056655093 | I38: =MEDIAN(I5:I10) -> 592000 | J38: =MEDIAN(J5:J10) -> 8650 | K38: =MEDIAN(K5:K10) -> 466.5 | L38: =MEDIAN(L5:L10) -> 1300 | M38: =MEDIAN(M5:M10) -> 0.013233831 | N38: =MEDIAN(N5:N10) -> 0.756323 | O38: =MEDIAN(O5:O10) -> 0.1494032 | ... Q38: =MEDIAN(Q5:Q10) -> 5.3404762 | R38: =COUNTIF(R5:R10,"Có")&"/6" -> 2/6 | S38: =COUNTIF(S5:S10,"Có")&"/6" -> 0/6 | U38: =COUNTIF(U5:U10,"Có")&"/6" -> 2/6
A39: Bài tập làm mẫu | B39: =COUNTA(I11:I18) -> 8 | E39: Trung vị (đếm 'Có' ở 3 cột cuối) | H39: =MEDIAN(H11:H18) -> 0.00140625 | I39: =MEDIAN(I11:I18) -> 616500 | J39: =MEDIAN(J11:J18) -> 6500 | K39: =MEDIAN(K11:K18) -> 404.5 | L39: =MEDIAN(L11:L18) -> 1600 | M39: =MEDIAN(M11:M18) -> 0.012536634 | N39: =MEDIAN(N11:N18) -> 0.89200676 | O39: =MEDIAN(O11:O18) -> 0.22356725 | ... Q39: =MEDIAN(Q11:Q18) -> 40.5 | R39: =COUNTIF(R11:R18,"Có")&"/8" -> 7/8 | S39: =COUNTIF(S11:S18,"Có")&"/8" -> 1/8 | U39: =COUNTIF(U11:U18,"Có")&"/8" -> 2/8
A40: Mẹo / giảng 1–3 phút | B40: =COUNTA(I19:I25) -> 7 | E40: Trung vị (đếm 'Có' ở 3 cột cuối) | H40: =MEDIAN(H19:H25) -> 0.0012418981 | I40: =MEDIAN(I19:I25) -> 213000 | J40: =MEDIAN(J19:J25) -> 4700 | K40: =MEDIAN(K19:K25) -> 682 | L40: =MEDIAN(L19:L25) -> 362 | M40: =MEDIAN(M19:M25) -> 0.020187793 | N40: =MEDIAN(N19:N25) -> 3.5876289 | O40: =MEDIAN(O19:O25) -> 0.078974359 | ... Q40: =MEDIAN(Q19:Q25) -> 33.6 | R40: =COUNTIF(R19:R25,"Có")&"/7" -> 6/7 | S40: =COUNTIF(S19:S25,"Có")&"/7" -> 0/7 | U40: =COUNTIF(U19:U25,"Có")&"/7" -> 5/7
A41: Có bán sản phẩm | B41: =COUNTA(I26:I30) -> 5 | E41: Trung vị (đếm 'Có' ở 3 cột cuối) | H41: =MEDIAN(H26:H30) -> 0.0011956019 | I41: =MEDIAN(I26:I30) -> 289000 | J41: =MEDIAN(J26:J30) -> 3800 | K41: =MEDIAN(K26:K30) -> 320 | L41: =MEDIAN(L26:L30) -> 198 | M41: =MEDIAN(M26:M30) -> 0.014765101 | N41: =MEDIAN(N26:N30) -> 1.884058 | O41: =MEDIAN(O26:O30) -> 0.069473684 | ... Q41: =MEDIAN(Q26:Q30) -> 28.025 | R41: =COUNTIF(R26:R30,"Có")&"/5" -> 3/5 | S41: =COUNTIF(S26:S30,"Có")&"/5" -> 5/5 | U41: =COUNTIF(U26:U30,"Có")&"/5" -> 3/5
A42: Video dài 11–16 phút | B42: =COUNTA(I31:I34) -> 4 | E42: Trung vị (đếm 'Có' ở 3 cột cuối) | H42: =MEDIAN(H31:H34) -> 0.00796875 | I42: =MEDIAN(I31:I34) -> 307500 | J42: =MEDIAN(J31:J34) -> 6600 | K42: =MEDIAN(K31:K34) -> 608.5 | L42: =MEDIAN(L31:L34) -> 630.5 | M42: =MEDIAN(M31:M34) -> 0.020895223 | N42: =MEDIAN(N31:N34) -> 1.9620233 | O42: =MEDIAN(O31:O34) -> 0.095291667 | ... Q42: =MEDIAN(Q31:Q34) -> 133.86 | R42: =COUNTIF(R31:R34,"Có")&"/4" -> 3/4 | S42: =COUNTIF(S31:S34,"Có")&"/4" -> 0/4 | U42: =COUNTIF(U31:U34,"Có")&"/4" -> 0/4
A43: Cả 30 video | B43: =COUNTA(I5:I34) -> 30 | E43: Trung vị (đếm 'Có' ở 3 cột cuối) | H43: =MEDIAN(H5:H34) -> 0.0012413194 | I43: =MEDIAN(I5:I34) -> 390500 | J43: =MEDIAN(J5:J34) -> 6150 | K43: =MEDIAN(K5:K34) -> 480 | L43: =MEDIAN(L5:L34) -> 740.5 | M43: =MEDIAN(M5:M34) -> 0.01492972 | N43: =MEDIAN(N5:N34) -> 1.1888533 | O43: =MEDIAN(O5:O34) -> 0.12030773 | ... Q43: =MEDIAN(Q5:Q34) -> 31.36 | R43: =COUNTIF(R5:R34,"Có")&"/30" -> 21/30 | S43: =COUNTIF(S5:S34,"Có")&"/30" -> 6/30 | U43: =COUNTIF(U5:U34,"Có")&"/30" -> 12/30
A45: Nguồn: lượt xem lấy từ lưới Reels (Facebook làm tròn, ví dụ 2,1 triệu, 709K); cảm xúc, bình luận, chia sẻ lấy từ trang từng Reel; ngày đăng lấy từ dữ liệu trang (creation_time). Đo ngày 08/10/2026.
A46: Dàn ý, kiểu mở đầu, lời mời và câu chào được đọc từ phụ đề in trên video qua 12–24 khung hình lấy mẫu mỗi video, không có bản ghi âm. 'Không thấy' = không xuất hiện trong khung lấy mẫu, có thể vẫn có trong lời nói. Video dài chỉ lấy mẫu thưa.
A47: Bối cảnh toàn kênh: trong 100 video nhiều view nhất chỉ có 8 video Nam Hà nói trực tiếp; còn lại là video chữ (danh sách chữ trên nền hoa/ảnh), cao nhất 9,2 triệu. Một video có thumbnail giống người nói ('Tuyệt chiêu dùng máy sấy tóc', 963K) thực tế là video chữ cuộn nên đã loại.
A48: Cụm đau lưng – vai gáy (7 video): 1,5 triệu · 1,2 triệu · 987K · 728K · 505K · 410K · 265K. Chủ đề tiền đình có cả bản 74 giây (201K) và bản 11 phút (159K). Chủ đề 'việc buổi sáng' quay lại sau 9 tháng: 289K (4/2025) → 194K (1/2026).
