Workbook

Sheet BS LÊ XUÂN HẢI
A1: THẺ QUY TẮC VIRAL · KÊNH PGS.TS.BS LÊ XUÂN HẢI
A2: Rút từ 30 video bác sĩ nói trực tiếp của PGS.TS.BS Lê Xuân Hải (69K theo dõi, miễn dịch – huyết học, y học tích hợp), đo ngày 07/10/2026. Số liệu từng video ở sheet "Số liệu Lê Xuân Hải". Cột "Áp dụng cho Bác sĩ Hội" theo DNA V1.3, sheet "Luật chung" và mã page P0–P13 trong file Phan-vai-14-page-Bac-si-Hoi.xlsx.
A4: SỐ CHÍNH
A5: # | B5: Chỉ số | D5: Giá trị | E5: Ghi chú
A6: 1 | B6: Video đã phân tích | D6: 30 video | E6: Lấy 20 video nhiều view nhất và 10 video ít view nhất trong 100 Reels gần nhất; chỉ tính video bác sĩ nói trực tiếp.
A7: 2 | B7: Trung vị lượt xem · 20 video top | D7: =MEDIAN('Số liệu Lê Xuân Hải'!I5:I24) -> 217000 | E7: Tổng 20 video top: 5,7 triệu lượt xem.
A8: 3 | B8: Trung vị lượt xem · 10 video đáy | D8: =MEDIAN('Số liệu Lê Xuân Hải'!I25:I34) -> 10000 | E8: Chênh khoảng 20 lần so với nhóm top.
A9: 4 | B9: Video lớn nhất | D9: =MAX('Số liệu Lê Xuân Hải'!I5:I24) -> 775000 | E9: Bệnh nhân ung thư phơi nắng thế nào? (cẩm nang) · 4:51 · 12/02/2026 · 3,8K chia sẻ.
A10: 5 | B10: Cảm xúc / lượt xem · top và đáy | D10: =TEXT(MEDIAN('Số liệu Lê Xuân Hải'!M5:M24),"0.0%")&" và "&TEXT(MEDIAN('Số liệu Lê Xuân Hải'!M25:M34),"0.0%") -> 2.0% và 2.0% | E10: Gần bằng nhau: ai đã xem video đáy vẫn thích, chỉ là Facebook không phát rộng. Khác biệt nằm ở chủ đề và 3 giây đầu.
A11: 6 | B11: Chủ đề đời thường / niềm tin | D11: =COUNTIF('Số liệu Lê Xuân Hải'!F5:F24,"Đời thường / niềm tin")&"/20 top · "&COUNTIF('Số liệu Lê Xuân Hải'!F25:F34,"Đời thường / niềm tin")&"/10 đáy" -> 19/20 top · 0/10 đáy | E11: Đời thường / niềm tin = ăn, uống, phơi, thở, mẹo hay bài thuốc đang lan truyền, lựa chọn điều trị.
A12: 7 | B12: Câu hỏi trong 10 giây đầu | D12: =COUNTIF('Số liệu Lê Xuân Hải'!R5:R24,"Có")&"/20 top · "&COUNTIF('Số liệu Lê Xuân Hải'!R25:R34,"Có")&"/10 đáy" -> 11/20 top · 3/10 đáy
A13: 8 | B13: Thân bài đánh số "thứ nhất – thứ hai – thứ ba" | D13: =COUNTIF('Số liệu Lê Xuân Hải'!S5:S24,"Có")&"/20 top · "&COUNTIF('Số liệu Lê Xuân Hải'!S25:S34,"Có")&"/10 đáy" -> 13/20 top · 5/10 đáy
A14: 9 | B14: Tốc độ nói trung vị · top | D14: =MEDIAN('Số liệu Lê Xuân Hải'!Q5:Q24) -> 168.00258 | E14: Tiếng/phút. Video nói nhanh nhất (242 tiếng/phút) nằm ở nhóm đáy.
A15: 10 | B15: Độ dài trung vị · top và đáy | D15: =TEXT(MEDIAN('Số liệu Lê Xuân Hải'!H5:H24),"[m]:ss")&" và "&TEXT(MEDIAN('Số liệu Lê Xuân Hải'!H25:H34),"[m]:ss") -> 3:05 và 3:30 | E15: Độ dài không tách được hai nhóm; chủ đề và hook mới tách được.
A16: 11 | B16: Cụm phơi nắng | D16: 8 video / 17 ngày · 2,27 triệu view | E16: Khi một chủ đề nổ, kênh làm liền cụm video trả lời câu hỏi con từ bình luận.
A17: 12 | B17: Nhịp đăng giai đoạn nổ | D17: ~1 video/ngày | E17: 14/20 video top đăng trong 16/01–12/02/2026. Từ tháng 5 đăng thưa và ít video lớn.
A19: A. BỘ QUY TẮC VIRAL
A20: Mức độ: Bắt buộc = làm ở mọi video · Nên = làm khi phù hợp · Thử nghiệm = chạy thử nhỏ, đo rồi mới nhân rộng (DNA quyết định 129–130).
A21: # | B21: Nhóm | C21: Quy tắc | D21: Làm thế nào | E21: Bằng chứng từ kênh Lê Xuân Hải | F21: Áp dụng cho Bác sĩ Hội | G21: Mức độ
A22: 1 | B22: Định dạng | C22: Bác sĩ nói trực tiếp, nhìn thẳng máy, khung dọc ngang ngực | D22: Ngồi giữa khung, mic cài áo, nói như đang trả lời một người cụ thể. | E22: 30/30 video phân tích là bác sĩ nói trực tiếp. Video không có bác sĩ nói (cảnh, vlog, chữ ghép ảnh) cao nhất 55K; 20 video top từ 98K đến 775K. | F22: Bác sĩ Hội nói trực tiếp, giọng 70% chuyên gia, 30% gần gũi (DNA ch.8). Xưng "tôi", gọi "cô chú" hoặc "anh chị" theo nhóm khách của từng page. | G22: Bắt buộc
A23: 2 | B23: Chủ đề | C23: Chọn việc người xem đang làm hằng ngày hoặc điều họ đang tin | D23: Ăn gì, uống gì, kiêng gì, làm lúc nào, mẹo hay bài thuốc trên mạng có đúng không. Không chọn kiểu "X là gì". | E23: 19/20 video top thuộc nhóm này; 10/10 video đáy là khái niệm, định nghĩa hoặc liệu pháp chuyên sâu. Video định nghĩa "Hội chứng rò rỉ ruột" chỉ 11K. | F23: P8: nhà có người đau dạ dày nấu gì. P10: cà phê, trà sữa, bỏ bữa sáng. P11: đi nhậu thế nào đỡ hại. P1: ăn tối mấy giờ, nằm nghiêng bên nào. Chủ đề bệnh học (HP, nội soi) vẫn làm nhưng mở bằng một câu hỏi đời thường. | G23: Bắt buộc
A24: 3 | B24: Chủ đề | C24: Biến mẹo dân gian, bài thuốc, trào lưu đang lan truyền thành video kiểm chứng | D24: Gọi đúng tên mẹo → điều đúng, điều chưa đúng, rủi ro → kết luận dùng thế nào cho an toàn. | E24: Nha đam – rượu – mật ong 504K (1,3K chia sẻ). Trào lưu nước cốt chanh 304K. Nhịn ăn, nước kiềm 144K. | F24: Dạng "Lầm tưởng – sự thật": nghệ + mật ong (P3), baking soda khi ợ chua (P1), kiêng chua cay tuyệt đối (P8). Kết luận theo DNA: không phủ nhận cực đoan, không hứa khỏi. | G24: Bắt buộc
A25: 4 | B25: Chủ đề | C25: Không lấy tên thuốc, liệu pháp hẹp hay ca bệnh hiếm làm chủ đề video | D25: Những chủ đề này chỉ chạm một nhóm rất nhỏ nên Facebook không phát rộng. | E25: Keytruda + Fucoidan 6,2K và 9,6K. Liệu pháp Ozone 10K. Đọc nguyên hồ sơ một ca u não 12K. | F25: Câu hỏi về thuốc cụ thể (thuốc dạ dày, phác đồ diệt HP) trả lời trong tin nhắn hoặc livestream. Nếu làm video: bác sĩ duyệt (DNA QĐ 110), không xúi ngừng thuốc (lằn ranh 4). | G25: Bắt buộc
A26: 5 | B26: Tiêu đề | C26: Tiêu đề là câu hỏi người bệnh hay hỏi, hiện bằng chữ to ngay khung hình đầu | D26: Khung chữ 2 dòng, chọn một khuôn ở mục C. Dòng phụ gọi đúng đối tượng. | E26: 19/20 video top có câu hỏi hoặc lời hứa bằng chữ ngay khung hình đầu. Video đáy "Viêm mạn tính" không có chữ tiêu đề: 10K. | F26: "Trào ngược có uống cà phê được không?" · "Nghệ mật ong có chữa được đau dạ dày?" · Dòng phụ: "Người trào ngược – xem để áp dụng". | G26: Bắt buộc
A27: 6 | B27: Hook lời | C27: 3 giây đầu: câu hỏi của người bệnh, một câu phản bác, hoặc một con số + lợi ích | D27: Không mở bằng "hôm nay chúng ta tìm hiểu…". Nếu chào thì một câu rồi vào câu hỏi ngay. | E27: Câu hỏi trong 10 giây đầu: 11/20 video top, 3/10 video đáy. 4/10 video đáy mở kiểu "buổi chia sẻ hôm nay" hoặc "chủ đề hôm nay". | F27: Hook 3 tầng DNA 14.25: gọi đúng tình trạng → mâu thuẫn → lời hứa. Ví dụ: "Uống thuốc thì đỡ nhưng dừng là trào ngược quay lại? Vấn đề có thể không chỉ nằm ở axit. Có 3 yếu tố cô chú cần xem lại." | G27: Bắt buộc
A28: 7 | B28: Hook lời | C28: Trả lời ngắn trong 10 giây đầu, rồi mới giải thích | D28: Đáp án có / không / tùy trường hợp, kèm số ý sẽ nói. | E28: Video thịt heo 173K: đọc câu hỏi, trả lời ngay là ăn được, rồi nêu 3 lưu ý. Video phơi nắng 9h 323K: trả lời ngay, rồi mới giải thích vì sao. | F28: "Nhiều người vẫn uống được, nhưng có 3 kiểu uống cô chú nên tránh." | G28: Bắt buộc
A29: 8 | B29: Hook lời | C29: Khi đã có video nổ, mở video sau bằng bằng chứng xã hội | D29: Nhắc video trước được nhiều người xem hoặc hỏi → hôm nay tổng hợp đầy đủ. | E29: Video lớn nhất kênh (775K) mở bằng việc video ngắn trước về ánh nắng đạt gần 300K lượt xem. | F29: Chỉ dùng số thật của chính page (Luật chung 4, lằn ranh 1). Mẫu: "Video về ợ chua ban đêm tuần trước có [số thật] câu hỏi. Hôm nay tôi trả lời đầy đủ." | G29: Nên
A30: 9 | B30: Kịch bản | C30: Thân bài 3 ý đánh số, mỗi ý một ví dụ đời thường | D30: "Thứ nhất – thứ hai – thứ ba". Mỗi ý: cơ chế giải thích dễ hiểu, góc y học cổ truyền nếu có cơ sở, một việc làm cụ thể. | E30: Thân bài đánh số: 13/20 video top, 5/10 video đáy. | F30: Khớp 6 bước giọng DNA ch.8.5: mâu thuẫn → đồng cảm → quan điểm → giải thích đời thường → giải pháp cụ thể → kết có định hướng. | G30: Bắt buộc
A31: 10 | B31: Kịch bản | C31: Mỗi video có một ẩn dụ đời thường cho cơ chế | D31: So sánh với thứ người xem gặp hằng ngày để họ nhớ và kể lại được. | E31: Video "Tây y hay Đông y" 324K dùng hình ảnh đám cháy và lớp lá khô. Video "Phơi nắng đúng chỗ" 325K ví như sạc pin cho hệ miễn dịch. | F31: Cơ vòng thực quản như cánh cửa (DNA ch.8.5); niêm mạc như lớp chống thấm; đường ruột như khu vườn vi sinh. | G31: Nên
A32: 11 | B32: Lập trường | C32: Cân bằng: tôn trọng điều trị chính thống, ghi nhận cách tự nhiên, chỉ chống cực đoan | D32: Nêu cả lợi và rủi ro; kết luận luôn nhắc hỏi bác sĩ đang điều trị. | E32: Nha đam 504K: phân tích hoạt chất rồi khẳng định chưa có bằng chứng thay phác đồ. Thanh lọc cơ thể 144K: cái nguy nằm ở sự cực đoan. Người theo cả hai phía cùng xem và chia sẻ. | F32: Trùng DNA ch.8.8: không hạ thấp phương pháp khác. Video thuốc Tây – thuốc Nam kết luận "phối hợp đúng", không xúi bỏ thuốc (lằn ranh 4). | G32: Bắt buộc
A33: 12 | B33: Cảm xúc | C33: Chọn góc mà người xem muốn gửi cho người thân | D33: Góc người chăm sóc ("nếu nhà bạn có người…") hoặc kiến thức tổng hợp dạng cẩm nang để lưu lại. | E33: Chia sẻ nhiều nhất: cẩm nang phơi nắng 3,8K; "Từ chối hoá trị" 1,6K (21% số cảm xúc); nha đam 1,3K. Teaser kiêng hải sản mở bằng góc người nhà: 169K. | F33: P9 (con cái chăm bố mẹ), P8 (người nấu cho cả nhà): "Nếu bố mẹ hay ợ chua về đêm…", "Nhà có người đau dạ dày, bữa tối nên nấu gì?" | G33: Nên
... A43: 22 | B43: Tránh | C43: Những thứ kéo video xuống đáy | D43: Định nghĩa "X là gì"; mở bằng "buổi chia sẻ hôm nay"; tên thuốc, liệu pháp hẹp; đọc nguyên hồ sơ ca hiếm; nói quá nhanh; không có chữ tiêu đề; đăng lại nguyên video. | E43: 10 video đáy: 6,2K–12K view. | F43: Soát bằng mục D trước khi đăng. | G43: Bắt buộc
A45: B1. KHUNG KỊCH BẢN VIDEO 2:00–3:00 (khoảng 380–540 tiếng)
A46: Mẫu: "Trào ngược có uống cà phê được không?" (P1 hoặc P10). Nội dung chuyên môn trong cột mẫu phải được bác sĩ duyệt trước khi quay.
A47: # | B47: Giây | C47: Phần | D47: Việc phải làm | E47: Cách kênh Lê Xuân Hải làm | F47: Mẫu cho Bác sĩ Hội | G47: Độ dài lời
A48: 1 | B48: 0–3 giây | C48: Hook + chữ tiêu đề | D48: Đọc câu hỏi của người bệnh hoặc nêu một câu phản bác; chữ tiêu đề hiện ngay. | E48: Đọc lại câu hỏi người xem gửi về. | F48: "Bác sĩ ơi, trào ngược có uống cà phê được không?" | G48: 10–20 tiếng
A49: 2 | B49: 3–10 giây | C49: Trả lời ngắn + hứa số ý | D49: Có / không / tùy trường hợp, kèm số ý sẽ nói. | E49: Trả lời ngay, báo trước sẽ có mấy lưu ý. | F49: "Nhiều người vẫn uống được, nhưng có 3 kiểu uống cô chú nên tránh." | G49: 20–35 tiếng
A50: 3 | B50: 10–25 giây | C50: Đồng cảm + hiểu lầm | D50: Gọi tên nỗi lo hoặc lời đồn mọi người đang tin. | E50: Nhắc lời kiêng khem trong nhà hoặc trào lưu trên mạng. | F50: "Nhiều cô chú nghe nói trào ngược là phải bỏ hẳn cà phê. Bỏ được vài hôm lại thèm, uống lại thì sợ." | G50: 40–60 tiếng
A51: 4 | B51: 25–55 giây | C51: Ý 1 | D51: Cơ chế + một ẩn dụ đời thường. | E51: Giải thích cơ chế hiện đại, thêm góc y học cổ truyền khi có cơ sở. | F51: "Thứ nhất, tránh uống lúc bụng đói. Cơ vòng giống như một cánh cửa…" | G51: 80–110 tiếng
A52: 5 | B52: 55–85 giây | C52: Ý 2 | D52: Một việc cụ thể làm được ngay. | E52: Mỗi ý kèm một việc làm cụ thể. | F52: "Thứ hai, uống loãng hơn, uống sau bữa sáng, không uống gần giờ ngủ." | G52: 80–110 tiếng
...

Sheet Số liệu Lê Xuân Hải
A1: Số liệu 30 video · PGS.TS.BS Lê Xuân Hải
A2: Kênh facebook.com/xuanhai.le.14/reels · 69K theo dõi · đo ngày 07/10/2026. 20 video nhiều view nhất và 10 video ít view nhất trong 100 Reels gần nhất, chỉ tính video bác sĩ nói trực tiếp (bỏ video chữ ghép ảnh, vlog, clip quay ngang). Cột M–O và Q là công thức; ô nền trắng còn lại là số đo.
A4: Nhóm | B4: # trên lưới Reels | C4: Link Reel | D4: Ngày đăng | E4: Tiêu đề trên màn hình | F4: Loại chủ đề | G4: Kiểu mở đầu (3–10 giây đầu) | H4: Thời lượng | I4: Lượt xem | J4: Cảm xúc | K4: Bình luận | L4: Chia sẻ | M4: Cảm xúc / lượt xem | N4: Bình luận / 1.000 lượt xem | O4: Chia sẻ / cảm xúc | P4: Số tiếng lời thoại | Q4: Tiếng / phút | R4: Câu hỏi trong 10 giây đầu | S4: Thân bài đánh số (thứ nhất…) | T4: Có mời bình luận
A5: Top | B5: 74 | C5: https://www.facebook.com/reel/2051360805639377 | D5: 46065 | E5: Bệnh nhân ung thư phơi nắng thế nào? (cẩm nang) | F5: Đời thường / niềm tin | G5: Bằng chứng xã hội: video trước gần 300K view | H5: 0.0033636574 | I5: 775000 | J5: 23200 | K5: 800 | L5: 3800 | M5: =J5/I5 -> 0.029935484 | N5: =K5/I5*1000 -> 1.0322581 | O5: =L5/J5 -> 0.1637931 | P5: 829 | Q5: =P5/(H5*1440) -> 171.15133 | R5: Không | S5: Có | T5: Không
A6: Top | B6: 86 | C6: https://www.facebook.com/reel/861392706896398 | D6: 46052 | E6: Ánh nắng có lợi nhiều hơn bạn nghĩ | F6: Đời thường / niềm tin | G6: Con số + lợi ích (15 phút mỗi ngày) | H6: 0.00028009259 | I6: 575000 | J6: 10800 | K6: 297 | L6: 1200 | M6: =J6/I6 -> 0.018782609 | N6: =K6/I6*1000 -> 0.51652174 | O6: =L6/J6 -> 0.11111111 | P6: 56 | Q6: =P6/(H6*1440) -> 138.84298 | R6: Không | S6: Không | T6: Không
A7: Top | B7: 50 | C7: https://www.facebook.com/reel/1288836496684221 | D7: 46111 | E7: Ung thư có nên dùng Nha đam – Rượu – Mật ong? | F7: Đời thường / niềm tin | G7: Đọc câu hỏi người xem về bài thuốc lan truyền | H7: 0.0023267708 | I7: 504000 | J7: 10000 | K7: 581 | L7: 1300 | M7: =J7/I7 -> 0.01984127 | N7: =K7/I7*1000 -> 1.1527778 | O7: =L7/J7 -> 0.13 | P7: 543 | Q7: =P7/(H7*1440) -> 162.06294 | R7: Có | S7: Có | T7: Không
A8: Top | B8: 96 | C8: https://www.facebook.com/reel/26181567814762805 | D8: 46042 | E8: Tại sao có người từ chối hóa trị? | F8: Đời thường / niềm tin | G8: Câu hỏi gây tranh luận, chữ to toàn màn hình | H8: 0.0026127778 | I8: 473000 | J8: 7700 | K8: 439 | L8: 1600 | M8: =J8/I8 -> 0.01627907 | N8: =K8/I8*1000 -> 0.92811839 | O8: =L8/J8 -> 0.20779221 | P8: 622 | Q8: =P8/(H8*1440) -> 165.32001 | R8: Có | S8: Có | T8: Không
A9: Top | B9: 77 | C9: https://www.facebook.com/reel/890532260479836 | D9: 46060 | E9: Phơi nắng đúng chỗ | F9: Đời thường / niềm tin | G9: Câu hỏi của bệnh nhân + nghi vấn "đau đâu phơi đó" | H9: 0.0015160069 | I9: 325000 | J9: 10000 | K9: 610 | L9: 941 | M9: =J9/I9 -> 0.030769231 | N9: =K9/I9*1000 -> 1.8769231 | O9: =L9/J9 -> 0.0941 | P9: 369 | Q9: =P9/(H9*1440) -> 169.02957 | R9: Có | S9: Có | T9: Có
A10: Top | B10: 93 | C10: https://www.facebook.com/reel/4135736596739513 | D10: 46045 | E10: Ung thư – đừng chỉ chọn "diệt" (Tây y hay Đông y) | F10: Đời thường / niềm tin | G10: Quan điểm + ẩn dụ chiến tranh | H10: 0.0049378819 | I10: 324000 | J10: 8200 | K10: 400 | L10: 1100 | M10: =J10/I10 -> 0.025308642 | N10: =K10/I10*1000 -> 1.2345679 | O10: =L10/J10 -> 0.13414634 | P10: 1273 | Q10: =P10/(H10*1440) -> 179.02975 | R10: Không | S10: Có | T10: Không
A11: Top | B11: 79 | C11: https://www.facebook.com/reel/1823766131669277 | D11: 46058 | E11: Phơi nắng lúc 9h sáng: nên hay không nên? | F11: Đời thường / niềm tin | G11: Câu hỏi người bệnh + phản bác ngay | H11: 0.0012359722 | I11: 323000 | J11: 7900 | K11: 1000 | L11: 650 | M11: =J11/I11 -> 0.024458204 | N11: =K11/I11*1000 -> 3.0959752 | O11: =L11/J11 -> 0.082278481 | P11: 242 | Q11: =P11/(H11*1440) -> 135.97033 | R11: Có | S11: Không | T11: Có
A12: Top | B12: 25 | C12: https://www.facebook.com/reel/1772530660763780 | D12: 46237 | E12: Ăn gì để diệt ung thư? | F12: Đời thường / niềm tin | G12: Đảo câu hỏi: dinh dưỡng không chữa nhưng đổi môi trường | H12: 0.0064486806 | I12: 308000 | J12: 5100 | K12: 169 | L12: 602 | M12: =J12/I12 -> 0.016558442 | N12: =K12/I12*1000 -> 0.5487013 | O12: =L12/J12 -> 0.11803922 | P12: 1736 | Q12: =P12/(H12*1440) -> 186.94608 | R12: Không | S12: Có | T12: Không
A13: Top | B13: 48 | C13: https://www.facebook.com/reel/849241631520987 | D13: 46114 | E13: Trào lưu uống nước cốt chanh chữa bách bệnh? | F13: Đời thường / niềm tin | G13: Lời chào kiểu chương trình; chữ tiêu đề nêu trào lưu | H13: 0.014922593 | I13: 304000 | J13: 5200 | K13: 461 | L13: 751 | M13: =J13/I13 -> 0.017105263 | N13: =K13/I13*1000 -> 1.5164474 | O13: =L13/J13 -> 0.14442308 | P13: 3360 | Q13: =P13/(H13*1440) -> 156.36246 | R13: Không | S13: Có | T13: Không
A14: Top | B14: 92 | C14: https://www.facebook.com/reel/1424437715739555 | D14: 46047 | E14: Tăng miễn dịch từ bữa ăn của bạn | F14: Đời thường / niềm tin | G14: Câu hỏi "Muốn…?" + lời khuyên ngay | H14: 0.00028163194 | I14: 234000 | J14: 4400 | K14: 95 | L14: 361 | M14: =J14/I14 -> 0.018803419 | N14: =K14/I14*1000 -> 0.40598291 | O14: =L14/J14 -> 0.082045455 | P14: 56 | Q14: =P14/(H14*1440) -> 138.08408 | R14: Có | S14: Không | T14: Không
A15: Top | B15: 76 | C15: https://www.facebook.com/reel/1204673261788837 | D15: 46061 | E15: Phơi nắng không sợ nám | F15: Đời thường / niềm tin | G15: Nỗi sợ cụ thể của một nhóm (sạm nám) | H15: 0.0016904282 | I15: 200000 | J15: 6800 | K15: 281 | L15: 873 | M15: =J15/I15 -> 0.034 | N15: =K15/I15*1000 -> 1.405 | O15: =L15/J15 -> 0.12838235 | P15: 416 | Q15: =P15/(H15*1440) -> 170.89687 | R15: Không | S15: Có | T15: Có
A16: Top | B16: 91 | C16: https://www.facebook.com/reel/829652570108221 | D16: 46048 | E16: Thở đúng cách tăng cường hệ miễn dịch | F16: Đời thường / niềm tin | G16: Hành động làm ngay (hít 4 – giữ 4 – thở 6) | H16: 0.00035045139 | I16: 182000 | J16: 3600 | K16: 88 | L16: 440 | M16: =J16/I16 -> 0.01978022 | N16: =K16/I16*1000 -> 0.48351648 | O16: =L16/J16 -> 0.12222222 | P16: 67 | Q16: =P16/(H16*1440) -> 132.76528 | R16: Có | S16: Không | T16: Không
... A34: Đáy | B34: 82 | C34: https://www.facebook.com/reel/1405849347889130 | D34: 46056 | E34: Keytruda có uống được Fucoidan không? (P2) | F34: Chuyên sâu / khái niệm | G34: Câu hỏi về thuốc chuyên sâu, phần 2 | H34: 0.00062858796 | I34: 6200 | J34: 92 | K34: 6 | L34: 5 | M34: =J34/I34 -> 0.01483871 | N34: =K34/I34*1000 -> 0.96774194 | O34: =L34/J34 -> 0.054347826 | P34: 172 | Q34: =P34/(H34*1440) -> 190.02025 | R34: Có | S34: Không | T34: Không
A36: Tổng hợp (công thức)
A37: Nhóm | E37: Chỉ số | H37: Thời lượng | I37: Lượt xem | J37: Cảm xúc | K37: Bình luận | L37: Chia sẻ | M37: Cảm xúc / lượt xem | N37: Bình luận / 1.000 | O37: Chia sẻ / cảm xúc | P37: Số tiếng | Q37: Tiếng / phút | R37: Câu hỏi 10 giây đầu | S37: Thân bài đánh số | T37: Mời bình luận
A38: Top 20 | E38: Trung vị (đếm "Có" ở 3 cột cuối) | H38: =MEDIAN(H5:H24) -> 0.0021419734 | I38: =MEDIAN(I5:I24) -> 217000 | J38: =MEDIAN(J5:J24) -> 5150 | K38: =MEDIAN(K5:K24) -> 236.5 | L38: =MEDIAN(L5:L24) -> 593.5 | M38: =MEDIAN(M5:M24) -> 0.020368396 | N38: =MEDIAN(N5:N24) -> 1.1915404 | O38: =MEDIAN(O5:O24) -> 0.11526961 | ... Q38: =MEDIAN(Q5:Q24) -> 168.00258 | R38: =COUNTIF(R5:R24,"Có")&"/20" -> 11/20 | S38: =COUNTIF(S5:S24,"Có")&"/20" -> 13/20 | T38: =COUNTIF(T5:T24,"Có")&"/20" -> 4/20
A39: Đáy 10 | E39: Trung vị (đếm "Có" ở 3 cột cuối) | H39: =MEDIAN(H25:H34) -> 0.0024335243 | I39: =MEDIAN(I25:I34) -> 10000 | J39: =MEDIAN(J25:J34) -> 217 | K39: =MEDIAN(K25:K34) -> 10 | L39: =MEDIAN(L25:L34) -> 13 | M39: =MEDIAN(M25:M34) -> 0.020003788 | N39: =MEDIAN(N25:N34) -> 1.033871 | O39: =MEDIAN(O25:O34) -> 0.064347291 | ... Q39: =MEDIAN(Q25:Q34) -> 177.01329 | R39: =COUNTIF(R25:R34,"Có")&"/10" -> 3/10 | S39: =COUNTIF(S25:S34,"Có")&"/10" -> 5/10 | T39: =COUNTIF(T25:T34,"Có")&"/10" -> 1/10
A41: Nguồn: lượt xem lấy từ lưới Reels; cảm xúc, bình luận, chia sẻ lấy từ trang từng Reel ngày 07/10/2026. Facebook hiển thị số đã làm tròn (ví dụ 23,2K) nên các cột này là số làm tròn.
A42: Số tiếng, câu hỏi 10 giây đầu, thân bài đánh số, mời bình luận: đếm từ lời thoại chép tự động bằng Whisper, có thể sai chính tả vài chỗ. "Câu hỏi 10 giây đầu" = có dấu hỏi trong phần lời 10 giây đầu.
A43: Cụm phơi nắng (8 video, 30/01–15/02/2026): #86 575K · #79 323K · #78 33K · #77 325K · #76 200K · #75 13K · #74 775K · #71 22K = 2,27 triệu view. #78, #75, #71 không nằm trong 30 video trên.
A44: Đăng lại: #95 "Ung thư máu và những điều bạn cần biết" (21/01/2026) 53K; cùng video đăng lại #85 (31/01/2026) 10K. Chuỗi hải sản: teaser #7 169K → phần 1 #6 85K → phần 2 #5 24K → phần 3 #4 53K.
